Workbook

Sheet Comparative Sales
B1: ZEEFLORA LIMITED | I1: ZEEFLORA LIMITED
B2: ACTUAL SALES IN RESPECTIVE CURRENCIES | I2: ACTUAL SALES IN RESPECTIVE CURRENCIES
B3: 2024 SALES | I3: 2025 SALES
B4: Period | C4: EUR | D4: USD | E4: KSH | F4: Ledger Sales Ksh | I4: Period | J4: EUR | K4: USD | L4: KSH | M4: Ledger Sales Ksh | N4: % ↑↓
C5: Sales | D5: Sales | E5: Sales | J5: Sales | K5: Sales | L5: Sales
B6: 45292 | C6: 119460.6 | D6: 183797.94 | E6: 304905.18 | F6: 50550063 | I6: 45292 | J6: 203820.02 | K6: 148686.8 | L6: 538436.56 | M6: 47118749 | N6: =M6/F6 -> 0.93212048
B7: 45323 | C7: 153927.07 | D7: 203989.9 | E7: 788854.14 | F7: 57904875 | I7: 45323 | J7: 220503.29 | K7: 182866 | L7: 714508.72 | M7: 53998212 | N7: =M7/F7 -> 0.93253308
B8: 45352 | C8: 89751.08 | D8: 145569.56 | E8: 575637.93 | F8: 34186320 | I8: 45352 | J8: 172918.26 | K8: 168311.1 | L8: 343810.35 | M8: 46124501 | N8: =M8/F8 -> 1.3492093
B9: 45383 | C9: 67407.7 | D9: 146245.75 | E9: 597310.35 | F9: 29507538 | I9: 45383 | J9: 115088 | K9: 116906.58 | L9: 969767.52 | M9: 32835570 | N9: =M9/F9 -> 1.1127858
B10: 45413 | C10: 82739.65 | D10: 180991.87 | E10: 17525.86 | F10: 35707980 | I10: 45413 | J10: 128346.5 | K10: 170757.56 | L10: 1110034.6 | M10: 41902597 | N10: =M10/F10 -> 1.1734799
B11: 45444 | C11: 71663 | D11: 179664.1 | E11: 0 | F11: 33069559 | I11: 45444 | J11: 88790.07 | K11: =187142.6+1004 -> 188146.6 | L11: 445112.18 | M11: 37972845 | N11: =M11/F11 -> 1.1482719
B12: 45474 | C12: 81255.28 | D12: 163487.33 | E12: 176340 | F12: 32555900 | I12: 45474 | J12: 89077.12 | K12: 152167.84 | L12: 991146.81 | M12: 34132951 | N12: =M12/F12 -> 1.0484413
B13: 45505 | C13: 94716 | D13: 166878.38 | E13: 573099.5 | F13: 35516617 | I13: 45505 | J13: 67824.78 | K13: 133296.65 | L13: 214732.75 | M13: 27594785 | N13: =M13/F13 -> 0.77695421
B14: 45536 | C14: 91741.9 | D14: 139998.95 | E14: 346318.62 | F14: 31550758 | I14: 45536 | J14: 86077.2 | K14: 153947.6 | L14: 331680.98 | M14: 33255585 | N14: =M14/F14 -> 1.0540344
B15: 45566 | C15: 105668.1 | D15: 188921.87 | E15: 361293.04 | F15: 39549422 | I15: 45566 | J15: 100271.4 | K15: 210098 | L15: 547720.71 | M15: 42803756 | N15: =M15/F15 -> 1.0822852
B16: 45597 | C16: 92000.8 | D16: 114018.93 | E16: 631234.98 | F16: 28057824 | I16: 45597 | J16: 89735 | K16: 189648.35 | L16: 496146.5 | M16: 38447512 | N16: =M16/F16 -> 1.3702956
B17: 45627 | C17: 118730.48 | D17: 121413.3 | E17: 1090420 | F17: 32914046 | I17: 45627 | N17: =M17/F17 -> 0
B18: Total | C18: =SUM(C6:C17) -> 1169061.7 | D18: =SUM(D6:D17) -> 1934977.9 | E18: =SUM(E6:E17) -> 5462939.6 | F18: =SUM(F6:F17) -> 4.410709e+08 | I18: Total | J18: =SUM(J6:J17) -> 1362451.6 | K18: =SUM(K6:K17) -> 1814833.1 | L18: =SUM(L6:L17) -> 6703097.7 | M18: =SUM(M6:M17) -> 4.3618706e+08 | N18: =M18/F18 -> 0.98892732

Sheet Jan 2025-Prodn & Sales Analysis
B1: ZEEFLORA LIMITED
B2: PERFORMANCE PER VARIETY ANALYSIS
B3: 45688
B4: Description | C4: Production -Qty | D4: Rejection | E4: Sellable / Available for Sale | F4: Sales - Qty Export | G4: Sales - Qty Local | H4: Total Sales - Qty | I4: Export Sales -KES | J4: Local Sales KES | K4: Total Sales- KES | L4: % Export Sales | M4: Average Export Price KES | N4: Average Export Price USD | O4: Area SQM | P4: Production Per SQM | Q4: Revenue / SQM- USD
B5: STANDARD ROSES
B6: Rose Madam Cerise | C6: 50302 | D6: 1068 | E6: =C6-D6 -> 49234 | F6: 51236 | G6: 4200 | H6: =F6+G6 -> 55436 | I6: 891715.41 | J6: 12672.4 | K6: =I6+J6 -> 904387.81 | L6: =F6/E6 -> 1.040663 | M6: =I6/F6 -> 17.404079 | N6: =M6/129.39 -> 0.13450869 | O6: 2109.0462 | P6: =C6/O6*12 -> 286.20711 | Q6: =(K6*12/O6)/129.39 -> 39.76941
B7: Rose Madam Red | C7: 142086 | D7: 510 | E7: =C7-D7 -> 141576 | F7: 96842 | G7: 40 | H7: =F7+G7 -> 96882 | I7: 2745792.4 | J7: 120.69 | K7: =I7+J7 -> 2745913.1 | L7: =F7/E7 -> 0.68402837 | M7: =I7/F7 -> 28.353322 | N7: =M7/129.39 -> 0.21913071 | O7: 8374.1538 | P7: =C7/O7*12 -> 203.60648 | Q7: =(K7*12/O7)/129.39 -> 30.410698
B8: Rose Jumilia Bicolour Pink | C8: 198812 | D8: 1895 | E8: =C8-D8 -> 196917 | F8: 164114 | G8: 5560 | H8: =F8+G8 -> 169674 | I8: 2816064.4 | J8: 16775.87 | K8: =I8+J8 -> 2832840.3 | L8: =F8/E8 -> 0.83341712 | M8: =I8/F8 -> 17.159197 | N8: =M8/129.39 -> 0.1326161 | O8: 8684.3077 | P8: =C8/O8*12 -> 274.71896 | Q8: =(K8*12/O8)/129.39 -> 30.252928
B9: Rose Trivia Pale Pink | C9: 92708 | D9: 838 | E9: =C9-D9 -> 91870 | F9: 95750 | G9: 8120 | H9: =F9+G9 -> 103870 | I9: 1555505 | J9: 24500.01 | K9: =I9+J9 -> 1580005 | L9: =F9/E9 -> 1.0422336 | M9: =I9/F9 -> 16.245483 | N9: =M9/129.39 -> 0.12555439 | O9: 5334.6462 | P9: =C9/O9*12 -> 208.54167 | Q9: =(K9*12/O9)/129.39 -> 27.4684
B10: Rose Athena White | C10: 228840 | D10: 1826 | E10: =C10-D10 -> 227014 | F10: 178402 | G10: 31740 | H10: =F10+G10 -> 210142 | I10: 2696254.4 | J10: 94463.81 | K10: =I10+J10 -> 2790718.2 | L10: =F10/E10 -> 0.78586343 | M10: =I10/F10 -> 15.113364 | N10: =M10/129.39 -> 0.11680473 | O10: 10545.231 | P10: =C10/O10*12 -> 260.40966 | Q10: =(K10*12/O10)/129.39 -> 24.543723
B11: Rose Kamala Red | C11: 137901 | D11: 1066 | E11: =C11-D11 -> 136835 | F11: 117074 | G11: 1620 | H11: =F11+G11 -> 118694 | I11: 2593477.8 | J11: 4887.94 | K11: =I11+J11 -> 2598365.8 | L11: =F11/E11 -> 0.85558519 | M11: =I11/F11 -> 22.152466 | N11: =M11/129.39 -> 0.17120694 | O11: 10048.985 | P11: =C11/O11*12 -> 164.67455 | Q11: =(K11*12/O11)/129.39 -> 23.980522
B12: Rose Pegasso White | C12: 76159 | D12: 3499 | E12: =C12-D12 -> 72660 | F12: 45430 | G12: 6840 | H12: =F12+G12 -> 52270 | I12: 1185824.9 | J12: 20637.94 | K12: =I12+J12 -> 1206462.8 | L12: =F12/E12 -> 0.62524085 | M12: =I12/F12 -> 26.102243 | N12: =M12/129.39 -> 0.20173308 | O12: 4962.4615 | P12: =C12/O12*12 -> 184.16425 | Q12: =(K12*12/O12)/129.39 -> 22.547445
B13: Rose Ace Cerise | C13: 65175 | D13: 1817 | E13: =C13-D13 -> 63358 | F13: 49200 | G13: 9460 | H13: =F13+G13 -> 58660 | I13: 717015.43 | J13: 28543.11 | K13: =I13+J13 -> 745558.54 | L13: =F13/E13 -> 0.77653966 | M13: =I13/F13 -> 14.573484 | N13: =M13/129.39 -> 0.11263223 | O13: 3349.6615 | P13: =C13/O13*12 -> 233.48628 | Q13: =(K13*12/O13)/129.39 -> 20.642455
B14: Rose Goldfinch | C14: 68091 | D14: 1089 | E14: =C14-D14 -> 67002 | F14: 61792 | G14: 10920 | H14: =F14+G14 -> 72712 | I14: 1021626.3 | J14: 32948.3 | K14: =I14+J14 -> 1054574.6 | L14: =F14/E14 -> 0.92224113 | M14: =I14/F14 -> 16.53331 | N14: =M14/129.39 -> 0.12777889 | O14: 4794.0923 | P14: =C14/O14*12 -> 170.43727 | Q14: =(K14*12/O14)/129.39 -> 20.401
B15: Rose Celeb Salmon Pink | C15: 65543 | D15: 1850 | E15: =C15-D15 -> 63693 | F15: 60588 | G15: 2900 | H15: =F15+G15 -> 63488 | I15: 1151658.5 | J15: 8750 | K15: =I15+J15 -> 1160408.5 | L15: =F15/E15 -> 0.95125053 | M15: =I15/F15 -> 19.008029 | N15: =M15/129.39 -> 0.14690493 | O15: 5371.8646 | P15: =C15/O15*12 -> 146.41397 | Q15: =(K15*12/O15)/129.39 -> 20.03394
B16: Rose Tiger | C16: 37140 | D16: 1054 | E16: =C16-D16 -> 36086 | F16: 28990 | G16: 4180 | H16: =F16+G16 -> 33170 | I16: 420489.24 | J16: 12612.08 | K16: =I16+J16 -> 433101.32 | L16: =F16/E16 -> 0.80335864 | M16: =I16/F16 -> 14.504631 | N16: =M16/129.39 -> 0.11210009 | O16: 2605.2923 | P16: =C16/O16*12 -> 171.06718 | Q16: =(K16*12/O16)/129.39 -> 15.417487
B17: Rose Moonwalk Yellow | C17: 22288 | D17: 1165 | E17: =C17-D17 -> 21123 | F17: 29262 | G17: 1900 | H17: =F17+G17 -> 31162 | I17: 475634.8 | J17: 5732.76 | K17: =I17+J17 -> 481367.56 | L17: =F17/E17 -> 1.3853146 | M17: =I17/F17 -> 16.25435 | N17: =M17/129.39 -> 0.12562293 | O17: 2977.4769 | P17: =C17/O17*12 -> 89.826389 | Q17: =(K17*12/O17)/129.39 -> 14.993705
... B21: Rose Indigo | C21: 40873 | D21: 1093 | E21: =C21-D21 -> 39780 | F21: 22400 | G21: 3440 | H21: =F21+G21 -> 25840 | I21: 301687.06 | J21: 10446.91 | K21: =I21+J21 -> 312133.97 | L21: =F21/E21 -> 0.56309703 | M21: =I21/F21 -> 13.468172 | N21: =M21/129.39 -> 0.10408975 | O21: 2357.1692 | P21: =C21/O21*12 -> 208.0784 | Q21: =(K21*12/O21)/129.39 -> 12.280917
B22: SUB TOTAL | C22: =SUM(C6:C21) -> 1430948 | D22: =SUM(D6:D21) -> 24010 | E22: =SUM(E6:E21) -> 1406938 | F22: =SUM(F6:F21) -> 1142380 | G22: =SUM(G6:G21) -> 132760 | H22: =SUM(H6:H21) -> 1275140 | I22: =SUM(I6:I21) -> 20633715 | J22: =SUM(J6:J21) -> 399333.21 | K22: =SUM(K6:K21) -> 21033049 | L22: =F22/E22 -> 0.81196186 | M22: =I22/F22 -> 18.062042 | N22: =M22/129.39 -> 0.1395938 | O22: =SUM(O6:O21) -> 86952.369 | P22: =C22/O22*12 -> 197.48025 | Q22: =(K22*12/O22)/129.39 -> 22.433722
B23: % | D23: =D22/C22 -> 0.016779086 | E23: =E22/C22 -> 0.98322091
B24: SPRAY ROSES
B25: Spray Rose Snowflake White | C25: 52420 | D25: 705 | E25: =C25-D25 -> 51715 | F25: 61000 | G25: 480 | H25: =F25+G25 -> 61480 | I25: 2321796.4 | J25: 1655.16 | K25: =I25+J25 -> 2323451.5 | L25: =F25/E25 -> 1.1795417 | M25: =I25/F25 -> 38.062235 | N25: =M25/129.39 -> 0.29416675 | O25: 5210.5846 | P25: =C25/O25*12 -> 120.7235 | Q25: =(K25*12/O25)/129.39 -> 41.354968
B26: Spray Rose Mirabel | C26: 71685 | D26: 1026 | E26: =C26-D26 -> 70659 | F26: 62050 | G26: 120 | H26: =F26+G26 -> 62170 | I26: 2958006 | J26: 413.79 | K26: =I26+J26 -> 2958419.8 | L26: =F26/E26 -> 0.87816131 | M26: =I26/F26 -> 47.671329 | N26: =M26/129.39 -> 0.36843132 | O26: 8436.1846 | P26: =C26/O26*12 -> 101.9679 | Q26: =(K26*12/O26)/129.39 -> 32.523273
B27: Spray Rose Lianne Pink | C27: 46727 | D27: 371 | E27: =C27-D27 -> 46356 | F27: 47480 | G27: 600 | H27: =F27+G27 -> 48080 | I27: 1756333.3 | J27: 2068.96 | K27: =I27+J27 -> 1758402.3 | L27: =F27/E27 -> 1.0242471 | M27: =I27/F27 -> 36.991014 | N27: =M27/129.39 -> 0.28588773 | O27: 5024.4923 | P27: =C27/O27*12 -> 111.59814 | Q27: =(K27*12/O27)/129.39 -> 32.456866
B28: Spray Rose Marisa Yellow | C28: 19767 | D28: 328 | E28: =C28-D28 -> 19439 | F28: 27430 | G28: 240 | H28: =F28+G28 -> 27670 | I28: 924502.37 | J28: 827.58 | K28: =I28+J28 -> 925329.95 | L28: =F28/E28 -> 1.4110808 | M28: =I28/F28 -> 33.70406 | N28: =M28/129.39 -> 0.26048427 | O28: 2667.3231 | P28: =C28/O28*12 -> 88.92961 | Q28: =(K28*12/O28)/129.39 -> 32.173739
B29: Spray Rose Reflex Bicolour | C29: 72219 | D29: 417 | E29: =C29-D29 -> 71802 | F29: 71700 | G29: 580 | H29: =F29+G29 -> 72280 | I29: 2534161.6 | J29: 2000 | K29: =I29+J29 -> 2536161.6 | L29: =F29/E29 -> 0.99857943 | M29: =I29/F29 -> 35.343955 | N29: =M29/129.39 -> 0.27315832 | O29: 7381.6615 | P29: =C29/O29*12 -> 117.40284 | Q29: =(K29*12/O29)/129.39 -> 31.864222
B30: Spray Rose Odilia Pink | C30: 50790 | D30: 667 | E30: =C30-D30 -> 50123 | F30: 41330 | G30: 9980 | H30: =F30+G30 -> 51310 | I30: 1603800.8 | J30: 34413.78 | K30: =I30+J30 -> 1638214.6 | L30: =F30/E30 -> 0.82457155 | M30: =I30/F30 -> 38.804763 | N30: =M30/129.39 -> 0.29990542 | O30: 5024.4923 | P30: =C30/O30*12 -> 121.30181 | Q30: =(K30*12/O30)/129.39 -> 30.238423
B31: Spray Rose Eileen | C31: 26052 | D31: 217 | E31: =C31-D31 -> 25835 | F31: 24240 | G31: 360 | H31: =F31+G31 -> 24600 | I31: 839574.91 | J31: 1241.38 | K31: =I31+J31 -> 840816.29 | L31: =F31/E31 -> 0.93826205 | M31: =I31/F31 -> 34.635929 | N31: =M31/129.39 -> 0.26768629 | O31: 2605.2923 | P31: =C31/O31*12 -> 119.99575 | Q31: =(K31*12/O31)/129.39 -> 29.931273
B32: Spray Rose Babe Orange | C32: 44074 | D32: 374 | E32: =C32-D32 -> 43700 | F32: 41225 | G32: 240 | H32: =F32+G32 -> 41465 | I32: 1394878.7 | J32: 827.58 | K32: =I32+J32 -> 1395706.3 | L32: =F32/E32 -> 0.94336384 | M32: =I32/F32 -> 33.835748 | N32: =M32/129.39 -> 0.26150203 | O32: 5148.5538 | P32: =C32/O32*12 -> 102.72555 | Q32: =(K32*12/O32)/129.39 -> 25.141391
B33: Spray Rose Sweet Sara | C33: 19077 | D33: 610 | E33: =C33-D33 -> 18467 | F33: 19340 | G33: 0 | H33: =F33+G33 -> 19340 | I33: 679930.28 | J33: 0 | K33: =I33+J33 -> 679930.28 | L33: =F33/E33 -> 1.0472735 | M33: =I33/F33 -> 35.156685 | N33: =M33/129.39 -> 0.27171099 | O33: 2605.2923 | P33: =C33/O33*12 -> 87.868835 | Q33: =(K33*12/O33)/129.39 -> 24.204073
B34: Spray Rose Good Mood | C34: 33823 | D34: 1220 | E34: =C34-D34 -> 32603 | F34: 34850 | G34: 240 | H34: =F34+G34 -> 35090 | I34: 1306134 | J34: 827.58 | K34: =I34+J34 -> 1306961.6 | L34: =F34/E34 -> 1.06892 | M34: =I34/F34 -> 37.478739 | N34: =M34/129.39 -> 0.28965715 | O34: 5027.4462 | P34: =C34/O34*12 -> 80.732043 | Q34: =(K34*12/O34)/129.39 -> 24.109929
B35: Spray Rose Tessa | C35: 23215 | D35: 334 | E35: =C35-D35 -> 22881 | F35: 17720 | G35: 1080 | H35: =F35+G35 -> 18800 | I35: 650216.71 | J35: 3724.14 | K35: =I35+J35 -> 653940.85 | L35: =F35/E35 -> 0.77444168 | M35: =I35/F35 -> 36.693945 | N35: =M35/129.39 -> 0.28359182 | O35: 2667.3231 | P35: =C35/O35*12 -> 104.44179 | Q35: =(K35*12/O35)/129.39 -> 22.737535
B36: Spray Rose Fancy | C36: 18672 | D36: 132 | E36: =C36-D36 -> 18540 | F36: 15710 | G36: 120 | H36: =F36+G36 -> 15830 | I36: 568844.45 | J36: 413.79 | K36: =I36+J36 -> 569258.24 | L36: =F36/E36 -> 0.84735707 | M36: =I36/F36 -> 36.209067 | N36: =M36/129.39 -> 0.2798444 | O36: 2357.1692 | P36: =C36/O36*12 -> 95.056391 | Q36: =(K36*12/O36)/129.39 -> 22.397477
... B52: Spray Rose Jalita | C52: 25543 | D52: 490 | E52: =C52-D52 -> 25053 | F52: 10780 | G52: 600 | H52: =F52+G52 -> 11380 | I52: 348793.17 | J52: 2068.96 | K52: =I52+J52 -> 350862.13 | L52: =F52/E52 -> 0.43028779 | M52: =I52/F52 -> 32.355582 | N52: =M52/129.39 -> 0.25006246 | O52: 4993.4769 | P52: =C52/O52*12 -> 61.383282 | Q52: =(K52*12/O52)/129.39 -> 6.5164937
B53: Spray Rose Wedding Party | C53: 23429 | D53: 618 | E53: =C53-D53 -> 22811 | F53: =9690+1080 -> 10770 | G53: 1040 | H53: =F53+G53 -> 11810 | I53: 331993.67 | J53: 3586.2 | K53: =I53+J53 -> 335579.87 | L53: =F53/E53 -> 0.47214063 | M53: =I53/F53 -> 30.825782 | N53: =M53/129.39 -> 0.23823929 | O53: 5009.7231 | P53: =C53/O53*12 -> 56.120467 | Q53: =(K53*12/O53)/129.39 -> 6.2124473
B54: SUB TOTAL | C54: =SUM(C25:C53) -> 813240 | D54: =SUM(D25:D53) -> 11679 | E54: =SUM(E25:E53) -> 801561 | F54: =SUM(F25:F53) -> 694260 | G54: =SUM(G25:G53) -> 39920 | H54: =SUM(H25:H53) -> 734180 | I54: =SUM(I25:I53) -> 25914062 | J54: =SUM(J25:J53) -> 137655.07 | K54: =SUM(K25:K53) -> 26051717 | L54: =F54/E54 -> 0.86613495 | M54: =I54/F54 -> 37.326163 | N54: =M54/129.39 -> 0.28847796 | O54: =SUM(O25:O53) -> 106988.31 | P54: =(C54/O54)*12 -> 91.214453 | Q54: =(K54*12/O54)/129.39 -> 22.582945
B55: % | D55: =D54/C54 -> 0.014361074 | E55: =E54/C54 -> 0.98563893
B57: GRAND TOTAL | C57: =C22+C54 -> 2244188 | D57: =D22+D54 -> 35689 | E57: =E22+E54 -> 2208499 | F57: =F22+F54 -> 1836640 | G57: =G22+G54 -> 172680 | H57: =H22+H54 -> 2009320 | I57: =I22+I54 -> 46547777 | J57: =J22+J54 -> 536988.28 | K57: =K22+K54 -> 47084766 | L57: =F57/(E57) -> 0.83162365 | M57: =I57/F57 -> 25.343985 | N57: =M57/129.39 -> 0.19587283 | O57: =O54+O22 -> 193940.68 | P57: =(C57/O57)*12 -> 138.85821 | Q57: =(K57*12/O57)/129.39 -> 22.516041
B58: % | D58: =D57/C57 -> 0.015902857 | E58: =E57/C57 -> 0.98409714
B60: Notes
...

Sheet Jan - Colour Code
B1: ZEEFLORA LIMITED
B2: PERFORMANCE PER VARIETY ANALYSIS
B3: 45658
B4: Description | C4: Production -Qty | D4: Rejection | E4: Sellable / Available for Sale | F4: Sales - Qty Export | G4: Sales - Qty Local | H4: Total Sales - Qty | I4: Export Sales -KES | J4: Local Sales KES | K4: Total Sales- KES | L4: % Export Sales | M4: Average Export Price KES | N4: Average Export Price USD | O4: Area SQM | P4: Production Per SQM | Q4: Revenue / SQM- USD
B5: STANDARD ROSES
B6: Rose Jumilia Bicolour Pink | C6: ='Jan 2025-Prodn & Sales Analysis'!C8 -> 198812 | D6: ='Jan 2025-Prodn & Sales Analysis'!D8 -> 1895 | E6: ='Jan 2025-Prodn & Sales Analysis'!E8 -> 196917 | F6: ='Jan 2025-Prodn & Sales Analysis'!F8 -> 164114 | G6: ='Jan 2025-Prodn & Sales Analysis'!G8 -> 5560 | H6: ='Jan 2025-Prodn & Sales Analysis'!H8 -> 169674 | I6: ='Jan 2025-Prodn & Sales Analysis'!I8 -> 2816064.4 | J6: ='Jan 2025-Prodn & Sales Analysis'!J8 -> 16775.87 | K6: ='Jan 2025-Prodn & Sales Analysis'!K8 -> 2832840.3 | L6: =(F6+F7)/(E6+E7) -> 0.8998466 | M6: =I6/F6 -> 17.159197 | N6: =M6/129.39 -> 0.1326161 | O6: ='Jan 2025-Prodn & Sales Analysis'!O8 -> 8684.3077 | P6: =C6/O6*12 -> 274.71896 | Q6: =(K6+K7)*12/(O6+O7)/129.39 -> 29.193329
B7: Rose Trivia Pale Pink | C7: ='Jan 2025-Prodn & Sales Analysis'!C9 -> 92708 | D7: ='Jan 2025-Prodn & Sales Analysis'!D9 -> 838 | E7: ='Jan 2025-Prodn & Sales Analysis'!E9 -> 91870 | F7: ='Jan 2025-Prodn & Sales Analysis'!F9 -> 95750 | G7: ='Jan 2025-Prodn & Sales Analysis'!G9 -> 8120 | H7: ='Jan 2025-Prodn & Sales Analysis'!H9 -> 103870 | I7: ='Jan 2025-Prodn & Sales Analysis'!I9 -> 1555505 | J7: ='Jan 2025-Prodn & Sales Analysis'!J9 -> 24500.01 | K7: ='Jan 2025-Prodn & Sales Analysis'!K9 -> 1580005 | M7: =I7/F7 -> 16.245483 | N7: =M7/129.39 -> 0.12555439 | O7: ='Jan 2025-Prodn & Sales Analysis'!O9 -> 5334.6462 | P7: =C7/O7*12 -> 208.54167
B8: Rose Madam Cerise | C8: ='Jan 2025-Prodn & Sales Analysis'!C6 -> 50302 | D8: ='Jan 2025-Prodn & Sales Analysis'!D6 -> 1068 | E8: ='Jan 2025-Prodn & Sales Analysis'!E6 -> 49234 | F8: ='Jan 2025-Prodn & Sales Analysis'!F6 -> 51236 | G8: ='Jan 2025-Prodn & Sales Analysis'!G6 -> 4200 | H8: ='Jan 2025-Prodn & Sales Analysis'!H6 -> 55436 | I8: ='Jan 2025-Prodn & Sales Analysis'!I6 -> 891715.41 | J8: ='Jan 2025-Prodn & Sales Analysis'!J6 -> 12672.4 | K8: ='Jan 2025-Prodn & Sales Analysis'!K6 -> 904387.81 | L8: =(F8+F9)/(E8+E9) -> 0.89203496 | M8: =I8/F8 -> 17.404079 | N8: =M8/129.39 -> 0.13450869 | O8: ='Jan 2025-Prodn & Sales Analysis'!O6 -> 2109.0462 | P8: =C8/O8*12 -> 286.20711 | Q8: =(K8+K9)*12/(O8+O9)/129.39 -> 28.032415
B9: Rose Ace Cerise | C9: ='Jan 2025-Prodn & Sales Analysis'!C13 -> 65175 | D9: ='Jan 2025-Prodn & Sales Analysis'!D13 -> 1817 | E9: ='Jan 2025-Prodn & Sales Analysis'!E13 -> 63358 | F9: ='Jan 2025-Prodn & Sales Analysis'!F13 -> 49200 | G9: ='Jan 2025-Prodn & Sales Analysis'!G13 -> 9460 | H9: ='Jan 2025-Prodn & Sales Analysis'!H13 -> 58660 | I9: ='Jan 2025-Prodn & Sales Analysis'!I13 -> 717015.43 | J9: ='Jan 2025-Prodn & Sales Analysis'!J13 -> 28543.11 | K9: ='Jan 2025-Prodn & Sales Analysis'!K13 -> 745558.54 | M9: =I9/F9 -> 14.573484 | N9: =M9/129.39 -> 0.11263223 | O9: ='Jan 2025-Prodn & Sales Analysis'!O13 -> 3349.6615 | P9: =C9/O9*12 -> 233.48628
B10: Rose Kamala Red | C10: ='Jan 2025-Prodn & Sales Analysis'!C11 -> 137901 | D10: ='Jan 2025-Prodn & Sales Analysis'!D11 -> 1066 | E10: ='Jan 2025-Prodn & Sales Analysis'!E11 -> 136835 | F10: ='Jan 2025-Prodn & Sales Analysis'!F11 -> 117074 | G10: ='Jan 2025-Prodn & Sales Analysis'!G11 -> 1620 | H10: ='Jan 2025-Prodn & Sales Analysis'!H11 -> 118694 | I10: ='Jan 2025-Prodn & Sales Analysis'!I11 -> 2593477.8 | J10: ='Jan 2025-Prodn & Sales Analysis'!J11 -> 4887.94 | K10: ='Jan 2025-Prodn & Sales Analysis'!K11 -> 2598365.8 | L10: =(F10+F11)/(C10+C11) -> 0.76402119 | M10: =I10/F10 -> 22.152466 | N10: =M10/129.39 -> 0.17120694 | O10: ='Jan 2025-Prodn & Sales Analysis'!O11 -> 10048.985 | P10: =C10/O10*12 -> 164.67455 | Q10: =(K10+K11)*12/(O10+O11)/129.39 -> 26.90333
B11: Rose Madam Red | C11: ='Jan 2025-Prodn & Sales Analysis'!C7 -> 142086 | D11: ='Jan 2025-Prodn & Sales Analysis'!D7 -> 510 | E11: ='Jan 2025-Prodn & Sales Analysis'!E7 -> 141576 | F11: ='Jan 2025-Prodn & Sales Analysis'!F7 -> 96842 | G11: ='Jan 2025-Prodn & Sales Analysis'!G7 -> 40 | H11: ='Jan 2025-Prodn & Sales Analysis'!H7 -> 96882 | I11: ='Jan 2025-Prodn & Sales Analysis'!I7 -> 2745792.4 | J11: ='Jan 2025-Prodn & Sales Analysis'!J7 -> 120.69 | K11: ='Jan 2025-Prodn & Sales Analysis'!K7 -> 2745913.1 | M11: =I11/F11 -> 28.353322 | N11: =M11/129.39 -> 0.21913071 | O11: ='Jan 2025-Prodn & Sales Analysis'!O7 -> 8374.1538 | P11: =C11/O11*12 -> 203.60648
B12: Rose Athena White | C12: ='Jan 2025-Prodn & Sales Analysis'!C10 -> 228840 | D12: ='Jan 2025-Prodn & Sales Analysis'!D10 -> 1826 | E12: ='Jan 2025-Prodn & Sales Analysis'!E10 -> 227014 | F12: ='Jan 2025-Prodn & Sales Analysis'!F10 -> 178402 | G12: ='Jan 2025-Prodn & Sales Analysis'!G10 -> 31740 | H12: ='Jan 2025-Prodn & Sales Analysis'!H10 -> 210142 | I12: ='Jan 2025-Prodn & Sales Analysis'!I10 -> 2696254.4 | J12: ='Jan 2025-Prodn & Sales Analysis'!J10 -> 94463.81 | K12: ='Jan 2025-Prodn & Sales Analysis'!K10 -> 2790718.2 | L12: =F12/E12 -> 0.78586343 | M12: =I12/F12 -> 15.113364 | N12: =M12/129.39 -> 0.11680473 | O12: ='Jan 2025-Prodn & Sales Analysis'!O10 -> 10545.231 | P12: =C12/O12*12 -> 260.40966 | Q12: =(K12*12/O12)/129.39 -> 24.543723
B13: Rose Pegasso White | C13: ='Jan 2025-Prodn & Sales Analysis'!C12 -> 76159 | D13: ='Jan 2025-Prodn & Sales Analysis'!D12 -> 3499 | E13: ='Jan 2025-Prodn & Sales Analysis'!E12 -> 72660 | F13: ='Jan 2025-Prodn & Sales Analysis'!F12 -> 45430 | G13: ='Jan 2025-Prodn & Sales Analysis'!G12 -> 6840 | H13: ='Jan 2025-Prodn & Sales Analysis'!H12 -> 52270 | I13: ='Jan 2025-Prodn & Sales Analysis'!I12 -> 1185824.9 | J13: ='Jan 2025-Prodn & Sales Analysis'!J12 -> 20637.94 | K13: ='Jan 2025-Prodn & Sales Analysis'!K12 -> 1206462.8 | L13: =F13/E13 -> 0.62524085 | M13: =I13/F13 -> 26.102243 | N13: =M13/129.39 -> 0.20173308 | O13: ='Jan 2025-Prodn & Sales Analysis'!O12 -> 4962.4615 | P13: =C13/O13*12 -> 184.16425 | Q13: =(K13*12/O13)/129.39 -> 22.547445
B14: Rose Celeb Salmon Pink | C14: ='Jan 2025-Prodn & Sales Analysis'!C14 -> 68091 | D14: ='Jan 2025-Prodn & Sales Analysis'!D14 -> 1089 | E14: ='Jan 2025-Prodn & Sales Analysis'!E14 -> 67002 | F14: ='Jan 2025-Prodn & Sales Analysis'!F14 -> 61792 | G14: ='Jan 2025-Prodn & Sales Analysis'!G14 -> 10920 | H14: ='Jan 2025-Prodn & Sales Analysis'!H14 -> 72712 | I14: ='Jan 2025-Prodn & Sales Analysis'!I14 -> 1021626.3 | J14: ='Jan 2025-Prodn & Sales Analysis'!J14 -> 32948.3 | K14: ='Jan 2025-Prodn & Sales Analysis'!K14 -> 1054574.6 | L14: =F14/E14 -> 0.92224113 | M14: =I14/F14 -> 16.53331 | N14: =M14/129.39 -> 0.12777889 | O14: ='Jan 2025-Prodn & Sales Analysis'!O14 -> 4794.0923 | P14: =C14/O14*12 -> 170.43727 | Q14: =(K14*12/O14)/129.39 -> 20.401
B15: Rose Goldfinch | C15: ='Jan 2025-Prodn & Sales Analysis'!C15 -> 65543 | D15: ='Jan 2025-Prodn & Sales Analysis'!D15 -> 1850 | E15: ='Jan 2025-Prodn & Sales Analysis'!E15 -> 63693 | F15: ='Jan 2025-Prodn & Sales Analysis'!F15 -> 60588 | G15: ='Jan 2025-Prodn & Sales Analysis'!G15 -> 2900 | H15: ='Jan 2025-Prodn & Sales Analysis'!H15 -> 63488 | I15: ='Jan 2025-Prodn & Sales Analysis'!I15 -> 1151658.5 | J15: ='Jan 2025-Prodn & Sales Analysis'!J15 -> 8750 | K15: ='Jan 2025-Prodn & Sales Analysis'!K15 -> 1160408.5 | L15: =(F15+F16)/(C15+C16) -> 1.0229873 | M15: =I15/F15 -> 19.008029 | N15: =M15/129.39 -> 0.14690493 | O15: ='Jan 2025-Prodn & Sales Analysis'!O15 -> 5371.8646 | P15: =C15/O15*12 -> 146.41397 | Q15: =(K15+K16)*12/(O15+O16)/129.39 -> 18.23653
B16: Rose Moonwalk Yellow | C16: ='Jan 2025-Prodn & Sales Analysis'!C17 -> 22288 | D16: ='Jan 2025-Prodn & Sales Analysis'!D17 -> 1165 | E16: ='Jan 2025-Prodn & Sales Analysis'!E17 -> 21123 | F16: ='Jan 2025-Prodn & Sales Analysis'!F17 -> 29262 | G16: ='Jan 2025-Prodn & Sales Analysis'!G17 -> 1900 | H16: ='Jan 2025-Prodn & Sales Analysis'!H17 -> 31162 | I16: ='Jan 2025-Prodn & Sales Analysis'!I17 -> 475634.8 | J16: ='Jan 2025-Prodn & Sales Analysis'!J17 -> 5732.76 | K16: ='Jan 2025-Prodn & Sales Analysis'!K17 -> 481367.56 | M16: =I16/F16 -> 16.25435 | N16: =M16/129.39 -> 0.12562293 | O16: ='Jan 2025-Prodn & Sales Analysis'!O17 -> 2977.4769 | P16: =C16/O16*12 -> 89.826389
B17: Rose Tiger | C17: ='Jan 2025-Prodn & Sales Analysis'!C16 -> 37140 | D17: ='Jan 2025-Prodn & Sales Analysis'!D16 -> 1054 | E17: ='Jan 2025-Prodn & Sales Analysis'!E16 -> 36086 | F17: ='Jan 2025-Prodn & Sales Analysis'!F16 -> 28990 | G17: ='Jan 2025-Prodn & Sales Analysis'!G16 -> 4180 | H17: ='Jan 2025-Prodn & Sales Analysis'!H16 -> 33170 | I17: ='Jan 2025-Prodn & Sales Analysis'!I16 -> 420489.24 | J17: ='Jan 2025-Prodn & Sales Analysis'!J16 -> 12612.08 | K17: ='Jan 2025-Prodn & Sales Analysis'!K16 -> 433101.32 | L17: =F17/E17 -> 0.80335864 | M17: =I17/F17 -> 14.504631 | N17: =M17/129.39 -> 0.11210009 | O17: ='Jan 2025-Prodn & Sales Analysis'!O16 -> 2605.2923 | P17: =C17/O17*12 -> 171.06718 | Q17: =(K17*12/O17)/129.39 -> 15.417487
B18: Rose Espana Bi-Color | C18: ='Jan 2025-Prodn & Sales Analysis'!C19 -> 79831 | D18: ='Jan 2025-Prodn & Sales Analysis'!D19 -> 1144 | E18: ='Jan 2025-Prodn & Sales Analysis'!E19 -> 78687 | F18: ='Jan 2025-Prodn & Sales Analysis'!F19 -> 57022 | G18: ='Jan 2025-Prodn & Sales Analysis'!G19 -> 6800 | H18: ='Jan 2025-Prodn & Sales Analysis'!H19 -> 63822 | I18: ='Jan 2025-Prodn & Sales Analysis'!I19 -> 726413.39 | J18: ='Jan 2025-Prodn & Sales Analysis'!J19 -> 20517.25 | K18: ='Jan 2025-Prodn & Sales Analysis'!K19 -> 746930.64 | L18: =(F18+F19+F20)/(C18+C19+C20) -> 0.68916744 | M18: =I18/F18 -> 12.739178 | N18: =M18/129.39 -> 0.098455659 | O18: ='Jan 2025-Prodn & Sales Analysis'!O19 -> 5302.1538 | P18: =C18/O18*12 -> 180.67601 | Q18: =(K18+K19+K20)*12/(O18+O19+O20)/129.39 -> 13.139556
B19: Rose Copacabana Orange | C19: ='Jan 2025-Prodn & Sales Analysis'!C18 -> 66101 | D19: ='Jan 2025-Prodn & Sales Analysis'!D18 -> 2126 | E19: ='Jan 2025-Prodn & Sales Analysis'!E18 -> 63975 | F19: ='Jan 2025-Prodn & Sales Analysis'!F18 -> 46515 | G19: ='Jan 2025-Prodn & Sales Analysis'!G18 -> 12780 | H19: ='Jan 2025-Prodn & Sales Analysis'!H18 -> 59295 | I19: ='Jan 2025-Prodn & Sales Analysis'!I18 -> 735273 | J19: ='Jan 2025-Prodn & Sales Analysis'!J18 -> 38560.35 | K19: ='Jan 2025-Prodn & Sales Analysis'!K18 -> 773833.35 | M19: =I19/F19 -> 15.807223 | N19: =M19/129.39 -> 0.12216727 | O19: ='Jan 2025-Prodn & Sales Analysis'!O18 -> 5173.3662 | P19: =C19/O19*12 -> 153.32609
B20: Rose Confidential | C20: ='Jan 2025-Prodn & Sales Analysis'!C20 -> 59098 | D20: ='Jan 2025-Prodn & Sales Analysis'!D20 -> 1970 | E20: ='Jan 2025-Prodn & Sales Analysis'!E20 -> 57128 | F20: ='Jan 2025-Prodn & Sales Analysis'!F20 -> 37763 | G20: ='Jan 2025-Prodn & Sales Analysis'!G20 -> 22260 | H20: ='Jan 2025-Prodn & Sales Analysis'!H20 -> 60023 | I20: ='Jan 2025-Prodn & Sales Analysis'!I20 -> 599283.26 | J20: ='Jan 2025-Prodn & Sales Analysis'!J20 -> 67163.79 | K20: ='Jan 2025-Prodn & Sales Analysis'!K20 -> 666447.05 | M20: =I20/F20 -> 15.869588 | N20: =M20/129.39 -> 0.12264926 | O20: ='Jan 2025-Prodn & Sales Analysis'!O20 -> 4962.4615 | P20: =C20/O20*12 -> 142.90811
B21: Rose Indigo | C21: ='Jan 2025-Prodn & Sales Analysis'!C21 -> 40873 | D21: ='Jan 2025-Prodn & Sales Analysis'!D21 -> 1093 | E21: ='Jan 2025-Prodn & Sales Analysis'!E21 -> 39780 | F21: ='Jan 2025-Prodn & Sales Analysis'!F21 -> 22400 | G21: ='Jan 2025-Prodn & Sales Analysis'!G21 -> 3440 | H21: ='Jan 2025-Prodn & Sales Analysis'!H21 -> 25840 | I21: ='Jan 2025-Prodn & Sales Analysis'!I21 -> 301687.06 | J21: ='Jan 2025-Prodn & Sales Analysis'!J21 -> 10446.91 | K21: ='Jan 2025-Prodn & Sales Analysis'!K21 -> 312133.97 | L21: =F21/E21 -> 0.56309703 | M21: =I21/F21 -> 13.468172 | N21: =M21/129.39 -> 0.10408975 | O21: ='Jan 2025-Prodn & Sales Analysis'!O21 -> 2357.1692 | P21: =C21/O21*12 -> 208.0784 | Q21: =(K21*12/O21)/129.39 -> 12.280917
B22: SUB TOTAL | C22: =SUM(C6:C21) -> 1430948 | D22: =SUM(D6:D21) -> 24010 | E22: =SUM(E6:E21) -> 1406938 | F22: =SUM(F6:F21) -> 1142380 | G22: =SUM(G6:G21) -> 132760 | H22: =SUM(H6:H21) -> 1275140 | I22: =SUM(I6:I21) -> 20633715 | J22: =SUM(J6:J21) -> 399333.21 | K22: =SUM(K6:K21) -> 21033049 | L22: =F22/E22 -> 0.81196186 | M22: =I22/F22 -> 18.062042 | N22: =M22/129.39 -> 0.1395938 | O22: =SUM(O6:O21) -> 86952.369 | P22: =C22/O22*12 -> 197.48025 | Q22: =(K22*12/O22)/129.39 -> 22.433722
B23: % | D23: =D22/C22 -> 0.016779086 | E23: =E22/C22 -> 0.98322091
B24: SPRAY ROSES
B25: Spray Rose Mirabel | C25: ='Jan 2025-Prodn & Sales Analysis'!C26 -> 71685 | D25: ='Jan 2025-Prodn & Sales Analysis'!D26 -> 1026 | E25: ='Jan 2025-Prodn & Sales Analysis'!E26 -> 70659 | F25: ='Jan 2025-Prodn & Sales Analysis'!F26 -> 62050 | G25: ='Jan 2025-Prodn & Sales Analysis'!G26 -> 120 | H25: ='Jan 2025-Prodn & Sales Analysis'!H26 -> 62170 | I25: ='Jan 2025-Prodn & Sales Analysis'!I26 -> 2958006 | J25: ='Jan 2025-Prodn & Sales Analysis'!J26 -> 413.79 | K25: ='Jan 2025-Prodn & Sales Analysis'!K26 -> 2958419.8 | L25: =(F25+F26)/(E25+E26) -> 0.87377201 | M25: =I25/F25 -> 47.671329 | N25: =M25/129.39 -> 0.36843132 | O25: ='Jan 2025-Prodn & Sales Analysis'!O26 -> 8436.1846 | P25: =C25/O25*12 -> 101.9679 | Q25: =(K25+K26)*12/(O25+O26)/129.39 -> 30.309861
B26: Spray Rose Dominica | C26: ='Jan 2025-Prodn & Sales Analysis'!C37 -> 13815 | D26: ='Jan 2025-Prodn & Sales Analysis'!D37 -> 190 | E26: ='Jan 2025-Prodn & Sales Analysis'!E37 -> 13625 | F26: ='Jan 2025-Prodn & Sales Analysis'!F37 -> 11595 | G26: ='Jan 2025-Prodn & Sales Analysis'!G37 -> 120 | H26: ='Jan 2025-Prodn & Sales Analysis'!H37 -> 11715 | I26: ='Jan 2025-Prodn & Sales Analysis'!I37 -> 568608.05 | J26: ='Jan 2025-Prodn & Sales Analysis'!J37 -> 413.79 | K26: ='Jan 2025-Prodn & Sales Analysis'!K37 -> 569021.84 | M26: =I26/F26 -> 49.039073 | N26: =M26/129.39 -> 0.37900203 | O26: ='Jan 2025-Prodn & Sales Analysis'!O37 -> 2357.1692 | P26: =C26/O26*12 -> 70.330122
B27: Spray Rose Eileen | C27: ='Jan 2025-Prodn & Sales Analysis'!C31 -> 26052 | D27: ='Jan 2025-Prodn & Sales Analysis'!D31 -> 217 | E27: ='Jan 2025-Prodn & Sales Analysis'!E31 -> 25835 | F27: ='Jan 2025-Prodn & Sales Analysis'!F31 -> 24240 | G27: ='Jan 2025-Prodn & Sales Analysis'!G31 -> 360 | H27: ='Jan 2025-Prodn & Sales Analysis'!H31 -> 24600 | I27: ='Jan 2025-Prodn & Sales Analysis'!I31 -> 839574.91 | J27: ='Jan 2025-Prodn & Sales Analysis'!J31 -> 1241.38 | K27: ='Jan 2025-Prodn & Sales Analysis'!K31 -> 840816.29 | L27: =(F27+F28)/(E27+E28) -> 0.86324021 | M27: =I27/F27 -> 34.635929 | N27: =M27/129.39 -> 0.26768629 | O27: ='Jan 2025-Prodn & Sales Analysis'!O31 -> 2605.2923 | P27: =C27/O27*12 -> 119.99575 | Q27: =(K27+K28)*12/(O27+O28)/129.39 -> 30.133543
B28: Spray Rose Odilia Pink | C28: ='Jan 2025-Prodn & Sales Analysis'!C30 -> 50790 | D28: ='Jan 2025-Prodn & Sales Analysis'!D30 -> 667 | E28: ='Jan 2025-Prodn & Sales Analysis'!E30 -> 50123 | F28: ='Jan 2025-Prodn & Sales Analysis'!F30 -> 41330 | G28: ='Jan 2025-Prodn & Sales Analysis'!G30 -> 9980 | H28: ='Jan 2025-Prodn & Sales Analysis'!H30 -> 51310 | I28: ='Jan 2025-Prodn & Sales Analysis'!I30 -> 1603800.8 | J28: ='Jan 2025-Prodn & Sales Analysis'!J30 -> 34413.78 | K28: ='Jan 2025-Prodn & Sales Analysis'!K30 -> 1638214.6 | M28: =I28/F28 -> 38.804763 | N28: =M28/129.39 -> 0.29990542 | O28: ='Jan 2025-Prodn & Sales Analysis'!O30 -> 5024.4923 | P28: =C28/O28*12 -> 121.30181
B29: Spray Rose Reflex Bicolour | C29: ='Jan 2025-Prodn & Sales Analysis'!C29 -> 72219 | D29: ='Jan 2025-Prodn & Sales Analysis'!D29 -> 417 | E29: ='Jan 2025-Prodn & Sales Analysis'!E29 -> 71802 | F29: ='Jan 2025-Prodn & Sales Analysis'!F29 -> 71700 | G29: ='Jan 2025-Prodn & Sales Analysis'!G29 -> 580 | H29: ='Jan 2025-Prodn & Sales Analysis'!H29 -> 72280 | I29: ='Jan 2025-Prodn & Sales Analysis'!I29 -> 2534161.6 | J29: ='Jan 2025-Prodn & Sales Analysis'!J29 -> 2000 | K29: ='Jan 2025-Prodn & Sales Analysis'!K29 -> 2536161.6 | L29: =(F29+F30)/(E29+E30) -> 0.98795812 | M29: =I29/F29 -> 35.343955 | N29: =M29/129.39 -> 0.27315832 | O29: ='Jan 2025-Prodn & Sales Analysis'!O29 -> 7381.6615 | P29: =C29/O29*12 -> 117.40284 | Q29: =(K29+K30)*12/(O29+O30)/129.39 -> 29.383716
B30: Spray Rose Fire Works Bi-Pink | C30: ='Jan 2025-Prodn & Sales Analysis'!C38 -> 16232 | D30: ='Jan 2025-Prodn & Sales Analysis'!D38 -> 257 | E30: ='Jan 2025-Prodn & Sales Analysis'!E38 -> 15975 | F30: ='Jan 2025-Prodn & Sales Analysis'!F38 -> 15020 | G30: ='Jan 2025-Prodn & Sales Analysis'!G38 -> 0 | H30: ='Jan 2025-Prodn & Sales Analysis'!H38 -> 15020 | I30: ='Jan 2025-Prodn & Sales Analysis'!I38 -> 588697.83 | J30: ='Jan 2025-Prodn & Sales Analysis'!J38 -> 0 | K30: ='Jan 2025-Prodn & Sales Analysis'!K38 -> 588697.83 | M30: =I30/F30 -> 39.194263 | N30: =M30/129.39 -> 0.3029157 | O30: ='Jan 2025-Prodn & Sales Analysis'!O38 -> 2481.2308 | P30: =C30/O30*12 -> 78.502976
B31: Spray Rose Lianne Pink | C31: ='Jan 2025-Prodn & Sales Analysis'!C27 -> 46727 | D31: ='Jan 2025-Prodn & Sales Analysis'!D27 -> 371 | E31: ='Jan 2025-Prodn & Sales Analysis'!E27 -> 46356 | F31: ='Jan 2025-Prodn & Sales Analysis'!F27 -> 47480 | G31: ='Jan 2025-Prodn & Sales Analysis'!G27 -> 600 | H31: ='Jan 2025-Prodn & Sales Analysis'!H27 -> 48080 | I31: ='Jan 2025-Prodn & Sales Analysis'!I27 -> 1756333.3 | J31: ='Jan 2025-Prodn & Sales Analysis'!J27 -> 2068.96 | K31: ='Jan 2025-Prodn & Sales Analysis'!K27 -> 1758402.3 | L31: =(F31+F32)/(E31+E32) -> 0.94169303 | M31: =I31/F31 -> 36.991014 | N31: =M31/129.39 -> 0.28588773 | O31: ='Jan 2025-Prodn & Sales Analysis'!O27 -> 5024.4923 | P31: =C31/O31*12 -> 111.59814 | Q31: =(K31+K32)*12/(O31+O32)/129.39 -> 29.086453
B32: Spray Rose Tessa | C32: ='Jan 2025-Prodn & Sales Analysis'!C35 -> 23215 | D32: ='Jan 2025-Prodn & Sales Analysis'!D35 -> 334 | E32: ='Jan 2025-Prodn & Sales Analysis'!E35 -> 22881 | F32: ='Jan 2025-Prodn & Sales Analysis'!F35 -> 17720 | G32: ='Jan 2025-Prodn & Sales Analysis'!G35 -> 1080 | H32: ='Jan 2025-Prodn & Sales Analysis'!H35 -> 18800 | I32: ='Jan 2025-Prodn & Sales Analysis'!I35 -> 650216.71 | J32: ='Jan 2025-Prodn & Sales Analysis'!J35 -> 3724.14 | K32: ='Jan 2025-Prodn & Sales Analysis'!K35 -> 653940.85 | M32: =I32/F32 -> 36.693945 | N32: =M32/129.39 -> 0.28359182 | O32: ='Jan 2025-Prodn & Sales Analysis'!O35 -> 2667.3231 | P32: =C32/O32*12 -> 104.44179
B33: Spray Rose Zadique | C33: ='Jan 2025-Prodn & Sales Analysis'!C47 -> 12932 | D33: ='Jan 2025-Prodn & Sales Analysis'!D47 -> 213 | E33: ='Jan 2025-Prodn & Sales Analysis'!E47 -> 12719 | F33: ='Jan 2025-Prodn & Sales Analysis'!F47 -> 12900 | G33: ='Jan 2025-Prodn & Sales Analysis'!G47 -> 600 | H33: ='Jan 2025-Prodn & Sales Analysis'!H47 -> 13500 | I33: ='Jan 2025-Prodn & Sales Analysis'!I47 -> 394463.91 | J33: ='Jan 2025-Prodn & Sales Analysis'!J47 -> 2068.97 | K33: ='Jan 2025-Prodn & Sales Analysis'!K47 -> 396532.88 | L33: =(F33+F34)/(E33+E34) -> 0.95933994 | M33: =I33/F33 -> 30.578598 | N33: =M33/129.39 -> 0.23632891 | O33: ='Jan 2025-Prodn & Sales Analysis'!O47 -> 2605.2923 | P33: =C33/O33*12 -> 59.564909 | Q33: =(K33+K34)*12/(O33+O34)/129.39 -> 21.436769
B34: Spray Rose Babe Orange | C34: ='Jan 2025-Prodn & Sales Analysis'!C32 -> 44074 | D34: ='Jan 2025-Prodn & Sales Analysis'!D32 -> 374 | E34: ='Jan 2025-Prodn & Sales Analysis'!E32 -> 43700 | F34: ='Jan 2025-Prodn & Sales Analysis'!F32 -> 41225 | G34: ='Jan 2025-Prodn & Sales Analysis'!G32 -> 240 | H34: ='Jan 2025-Prodn & Sales Analysis'!H32 -> 41465 | I34: ='Jan 2025-Prodn & Sales Analysis'!I32 -> 1394878.7 | J34: ='Jan 2025-Prodn & Sales Analysis'!J32 -> 827.58 | K34: ='Jan 2025-Prodn & Sales Analysis'!K32 -> 1395706.3 | M34: =I34/F34 -> 33.835748 | N34: =M34/129.39 -> 0.26150203 | O34: ='Jan 2025-Prodn & Sales Analysis'!O32 -> 5148.5538 | P34: =C34/O34*12 -> 102.72555
B35: Spray Rose Fancy | C35: ='Jan 2025-Prodn & Sales Analysis'!C36 -> 18672 | D35: ='Jan 2025-Prodn & Sales Analysis'!D36 -> 132 | E35: ='Jan 2025-Prodn & Sales Analysis'!E36 -> 18540 | F35: ='Jan 2025-Prodn & Sales Analysis'!F36 -> 15710 | G35: ='Jan 2025-Prodn & Sales Analysis'!G36 -> 120 | H35: ='Jan 2025-Prodn & Sales Analysis'!H36 -> 15830 | I35: ='Jan 2025-Prodn & Sales Analysis'!I36 -> 568844.45 | J35: ='Jan 2025-Prodn & Sales Analysis'!J36 -> 413.79 | K35: ='Jan 2025-Prodn & Sales Analysis'!K36 -> 569258.24 | L35: =(F35+F36+F37+F38)/(E35+E36+E37+E38) -> 0.89133769 | M35: =I35/F35 -> 36.209067 | N35: =M35/129.39 -> 0.2798444 | O35: ='Jan 2025-Prodn & Sales Analysis'!O36 -> 2357.1692 | P35: =C35/O35*12 -> 95.056391 | Q35: =(K35+K36+K37+K38)*12/(O35+O36+O37+O38)/129.39 -> 20.552252
B36: Spray Rose Dinara | C36: ='Jan 2025-Prodn & Sales Analysis'!C41 -> 17268 | D36: ='Jan 2025-Prodn & Sales Analysis'!D41 -> 421 | E36: ='Jan 2025-Prodn & Sales Analysis'!E41 -> 16847 | F36: ='Jan 2025-Prodn & Sales Analysis'!F41 -> 19940 | G36: ='Jan 2025-Prodn & Sales Analysis'!G41 -> 120 | H36: ='Jan 2025-Prodn & Sales Analysis'!H41 -> 20060 | I36: ='Jan 2025-Prodn & Sales Analysis'!I41 -> 709630.66 | J36: ='Jan 2025-Prodn & Sales Analysis'!J41 -> 413.79 | K36: ='Jan 2025-Prodn & Sales Analysis'!K41 -> 710044.45 | M36: =I36/F36 -> 35.588298 | N36: =M36/129.39 -> 0.27504674 | O36: ='Jan 2025-Prodn & Sales Analysis'!O41 -> 3225.6 | P36: =C36/O36*12 -> 64.241071
B37: Spray Rose Good Mood | C37: ='Jan 2025-Prodn & Sales Analysis'!C34 -> 33823 | D37: ='Jan 2025-Prodn & Sales Analysis'!D34 -> 1220 | E37: ='Jan 2025-Prodn & Sales Analysis'!E34 -> 32603 | F37: ='Jan 2025-Prodn & Sales Analysis'!F34 -> 34850 | G37: ='Jan 2025-Prodn & Sales Analysis'!G34 -> 240 | H37: ='Jan 2025-Prodn & Sales Analysis'!H34 -> 35090 | I37: ='Jan 2025-Prodn & Sales Analysis'!I34 -> 1306134 | J37: ='Jan 2025-Prodn & Sales Analysis'!J34 -> 827.58 | K37: ='Jan 2025-Prodn & Sales Analysis'!K34 -> 1306961.6 | M37: =I37/F37 -> 37.478739 | N37: =M37/129.39 -> 0.28965715 | O37: ='Jan 2025-Prodn & Sales Analysis'!O34 -> 5027.4462 | P37: =C37/O37*12 -> 80.732043
B38: Spray Rose Sweet Blossoms | C38: ='Jan 2025-Prodn & Sales Analysis'!C48 -> 20267 | D38: ='Jan 2025-Prodn & Sales Analysis'!D48 -> 232 | E38: ='Jan 2025-Prodn & Sales Analysis'!E48 -> 20035 | F38: ='Jan 2025-Prodn & Sales Analysis'!F48 -> 7960 | G38: ='Jan 2025-Prodn & Sales Analysis'!G48 -> 4420 | H38: ='Jan 2025-Prodn & Sales Analysis'!H48 -> 12380 | I38: ='Jan 2025-Prodn & Sales Analysis'!I48 -> 299619.7 | J38: ='Jan 2025-Prodn & Sales Analysis'!J48 -> 15241.37 | K38: ='Jan 2025-Prodn & Sales Analysis'!K48 -> 314861.07 | M38: =I38/F38 -> 37.640666 | N38: =M38/129.39 -> 0.29090862 | O38: ='Jan 2025-Prodn & Sales Analysis'!O48 -> 2481.2308 | P38: =C38/O38*12 -> 98.017485
B39: Spray Rose Royal Porcelina Cream | C39: ='Jan 2025-Prodn & Sales Analysis'!C44 -> 32560 | D39: ='Jan 2025-Prodn & Sales Analysis'!D44 -> 243 | E39: ='Jan 2025-Prodn & Sales Analysis'!E44 -> 32317 | F39: ='Jan 2025-Prodn & Sales Analysis'!F44 -> 21090 | G39: ='Jan 2025-Prodn & Sales Analysis'!G44 -> 6920 | H39: ='Jan 2025-Prodn & Sales Analysis'!H44 -> 28010 | I39: ='Jan 2025-Prodn & Sales Analysis'!I44 -> 839447.71 | J39: ='Jan 2025-Prodn & Sales Analysis'!J44 -> 23862.06 | K39: ='Jan 2025-Prodn & Sales Analysis'!K44 -> 863309.77 | L39: =(F39+F40)/(E39+E40) -> 0.79611689 | M39: =I39/F39 -> 39.803116 | N39: =M39/129.39 -> 0.30762127 | O39: ='Jan 2025-Prodn & Sales Analysis'!O44 -> 4652.3077 | P39: =C39/O39*12 -> 83.984127 | Q39: =(K39+K40)*12/(O39+O40)/129.39 -> 19.720639
B40: Spray Rose Sweet Sara | C40: ='Jan 2025-Prodn & Sales Analysis'!C33 -> 19077 | D40: ='Jan 2025-Prodn & Sales Analysis'!D33 -> 610 | E40: ='Jan 2025-Prodn & Sales Analysis'!E33 -> 18467 | F40: ='Jan 2025-Prodn & Sales Analysis'!F33 -> 19340 | G40: ='Jan 2025-Prodn & Sales Analysis'!G33 -> 0 | H40: ='Jan 2025-Prodn & Sales Analysis'!H33 -> 19340 | I40: ='Jan 2025-Prodn & Sales Analysis'!I33 -> 679930.28 | J40: ='Jan 2025-Prodn & Sales Analysis'!J33 -> 0 | K40: ='Jan 2025-Prodn & Sales Analysis'!K33 -> 679930.28 | M40: =I40/F40 -> 35.156685 | N40: =M40/129.39 -> 0.27171099 | O40: ='Jan 2025-Prodn & Sales Analysis'!O33 -> 2605.2923 | P40: =C40/O40*12 -> 87.868835
...

Sheet Feb 2025 -Prodn& Sales Analysis
B1: ZEEFLORA LIMITED
B2: PERFORMANCE PER VARIETY ANALYSIS
B3: 45716
B4: Description | C4: Production -Qty | D4: Rejection | E4: Sellable / Available for Sale | F4: Sales - Qty Export | G4: Sales - Qty Local | H4: Total Sales - Qty | I4: Export Sales -KES | J4: Local Sales KES | K4: Total Sales- KES | L4: % Export Sales | M4: Average Export Price KES | N4: Average Export Price USD | O4: Area SQM | P4: Production Per SQM | Q4: Revenue / SQM- USD
B5: STANDARD ROSES
B6: Rose Madam Red | C6: 105693 | D6: 651 | E6: =C6-D6 -> 105042 | F6: 136996 | G6: 480 | H6: =F6+G6 -> 137476 | I6: 4232224.8 | J6: 1448.28 | K6: =I6+J6 -> 4233673.1 | L6: =F6/E6 -> 1.3042021 | M6: =I6/F6 -> 30.893054 | N6: =M6/129.3029 -> 0.23892004 | O6: 8374.1538 | P6: =C6/O6*12 -> 151.45602 | Q6: =(K6*12/O6)/129.3029 -> 46.919066
B7: Rose Kamala Red | C7: 137469 | D7: 790 | E7: =C7-D7 -> 136679 | F7: 146832 | G7: 7280 | H7: =F7+G7 -> 154112 | I7: 4537885 | J7: 74706.91 | K7: =I7+J7 -> 4612591.9 | L7: =F7/E7 -> 1.0742835 | M7: =I7/F7 -> 30.905286 | N7: =M7/129.3029 -> 0.23901464 | O7: 10048.985 | P7: =C7/O7*12 -> 164.15868 | Q7: =(K7*12/O7)/129.3029 -> 42.598649
B8: Rose Ace Cerise | C8: 70724 | D8: 1041 | E8: =C8-D8 -> 69683 | F8: 62146 | G8: 5900 | H8: =F8+G8 -> 68046 | I8: 1165098.1 | J8: 18836.21 | K8: =I8+J8 -> 1183934.3 | L8: =F8/E8 -> 0.89183876 | M8: =I8/F8 -> 18.747757 | N8: =M8/129.3029 -> 0.144991 | O8: 3349.6615 | P8: =C8/O8*12 -> 253.3653 | Q8: =(K8*12/O8)/129.3029 -> 32.80195
B9: Rose Madam Cerise | C9: 38310 | D9: 755 | E9: =C9-D9 -> 37555 | F9: 33306 | G9: 100 | H9: =F9+G9 -> 33406 | I9: 729754.14 | J9: 301.72 | K9: =I9+J9 -> 730055.86 | L9: =F9/E9 -> 0.88685927 | M9: =I9/F9 -> 21.910591 | N9: =M9/129.3029 -> 0.16945166 | O9: 2109.0462 | P9: =C9/O9*12 -> 217.97532 | Q9: =(K9*12/O9)/129.3029 -> 32.124989
B10: Rose Pegasso White | C10: 64760 | D10: 2249 | E10: =C10-D10 -> 62511 | F10: 60140 | G10: 15240 | H10: =F10+G10 -> 75380 | I10: 1544795.7 | J10: 47819.01 | K10: =I10+J10 -> 1592614.7 | L10: =F10/E10 -> 0.96207068 | M10: =I10/F10 -> 25.686659 | N10: =M10/129.3029 -> 0.19865493 | O10: 4962.4615 | P10: =C10/O10*12 -> 156.5997 | Q10: =(K10*12/O10)/129.3029 -> 29.784241
B11: Rose Jumilia Bicolour Pink | C11: 136880 | D11: 1285 | E11: =C11-D11 -> 135595 | F11: 142180 | G11: 4640 | H11: =F11+G11 -> 146820 | I11: 2634218.5 | J11: 14206.89 | K11: =I11+J11 -> 2648425.4 | L11: =F11/E11 -> 1.0485637 | M11: =I11/F11 -> 18.527349 | N11: =M11/129.3029 -> 0.14328642 | O11: 8684.3077 | P11: =C11/O11*12 -> 189.14116 | Q11: =(K11*12/O11)/129.3029 -> 28.302547
B12: Rose Trivia Pale Pink | C12: 97855 | D12: 691 | E12: =C12-D12 -> 97164 | F12: 95990 | G12: 1480 | H12: =F12+G12 -> 97470 | I12: 1542245.9 | J12: 4672.42 | K12: =I12+J12 -> 1546918.3 | L12: =F12/E12 -> 0.98791734 | M12: =I12/F12 -> 16.066735 | N12: =M12/129.3029 -> 0.12425657 | O12: 5334.6462 | P12: =C12/O12*12 -> 220.11957 | Q12: =(K12*12/O12)/129.3029 -> 26.911304
B13: Rose Athena White | C13: 173760 | D13: 2121 | E13: =C13-D13 -> 171639 | F13: 178886 | G13: 11260 | H13: =F13+G13 -> 190146 | I13: 2630888.1 | J13: 35810.34 | K13: =I13+J13 -> 2666698.4 | L13: =F13/E13 -> 1.0422223 | M13: =I13/F13 -> 14.707065 | N13: =M13/129.3029 -> 0.11374119 | O13: 10545.231 | P13: =C13/O13*12 -> 197.73109 | Q13: =(K13*12/O13)/129.3029 -> 23.468796
B14: Rose Celeb Salmon Pink | C14: 60710 | D14: 1122 | E14: =C14-D14 -> 59588 | F14: 58310 | G14: 1560 | H14: =F14+G14 -> 59870 | I14: 1219560.2 | J14: 4706.89 | K14: =I14+J14 -> 1224267.1 | L14: =F14/E14 -> 0.97855273 | M14: =I14/F14 -> 20.915113 | N14: =M14/129.3029 -> 0.16175285 | O14: 5371.8646 | P14: =C14/O14*12 -> 135.61771 | Q14: =(K14*12/O14)/129.3029 -> 21.150669
B15: Rose Espana Bi-Color | C15: 84656 | D15: 872 | E15: =C15-D15 -> 83784 | F15: 80564 | G15: 3160 | H15: =F15+G15 -> 83724 | I15: 1061007.9 | J15: 9534.5 | K15: =I15+J15 -> 1070542.4 | L15: =F15/E15 -> 0.96156784 | M15: =I15/F15 -> 13.169753 | N15: =M15/129.3029 -> 0.10185195 | O15: 5302.1538 | P15: =C15/O15*12 -> 191.5961 | Q15: =(K15*12/O15)/129.3029 -> 18.738057
B16: Rose Goldfinch | C16: 70675 | D16: 776 | E16: =C16-D16 -> 69899 | F16: 57584 | G16: 3220 | H16: =F16+G16 -> 60804 | I16: 940660.26 | J16: 9715.53 | K16: =I16+J16 -> 950375.79 | L16: =F16/E16 -> 0.82381722 | M16: =I16/F16 -> 16.335445 | N16: =M16/129.3029 -> 0.12633471 | O16: 4794.0923 | P16: =C16/O16*12 -> 176.90523 | Q16: =(K16*12/O16)/129.3029 -> 18.397633
B17: Rose Confidential | C17: 60082 | D17: 842 | E17: =C17-D17 -> 59240 | F17: 56124 | G17: 4340 | H17: =F17+G17 -> 60464 | I17: 857485.49 | J17: 13094.82 | K17: =I17+J17 -> 870580.31 | L17: =F17/E17 -> 0.94740041 | M17: =I17/F17 -> 15.27841 | N17: =M17/129.3029 -> 0.11815984 | O17: 4962.4615 | P17: =C17/O17*12 -> 145.28757 | Q17: =(K17*12/O17)/129.3029 -> 16.281135
... B19: Rose Copacabana Orange | C19: 61225 | D19: 969 | E19: =C19-D19 -> 60256 | F19: 52108 | G19: 3240 | H19: =F19+G19 -> 55348 | I19: 842366.24 | J19: 9775.88 | K19: =I19+J19 -> 852142.12 | L19: =F19/E19 -> 0.86477695 | M19: =I19/F19 -> 16.165776 | N19: =M19/129.3029 -> 0.12502253 | O19: 5173.3662 | P19: =C19/O19*12 -> 142.01585 | Q19: =(K19*12/O19)/129.3029 -> 15.286631
B20: Rose Moonwalk Yellow | C20: 27130 | D20: 587 | E20: =C20-D20 -> 26543 | F20: 27318 | G20: 640 | H20: =F20+G20 -> 27958 | I20: 418574.05 | J20: 1931.04 | K20: =I20+J20 -> 420505.09 | L20: =F20/E20 -> 1.0291979 | M20: =I20/F20 -> 15.32228 | N20: =M20/129.3029 -> 0.11849912 | O20: 2977.4769 | P20: =C20/O20*12 -> 109.3409 | Q20: =(K20*12/O20)/129.3029 -> 13.106775 | R20: To Replace
B21: Rose Tiger | C21: 26607 | D21: 591 | E21: =C21-D21 -> 26016 | F21: 20035 | G21: 940 | H21: =F21+G21 -> 20975 | I21: 299096.01 | J21: 2836.21 | K21: =I21+J21 -> 301932.22 | L21: =F21/E21 -> 0.77010301 | M21: =I21/F21 -> 14.928675 | N21: =M21/129.3029 -> 0.11545507 | O21: 2605.2923 | P21: =C21/O21*12 -> 122.55208 | Q21: =(K21*12/O21)/129.3029 -> 10.755386
B22: SUB TOTAL | C22: =SUM(C6:C21) -> 1256796 | D22: =SUM(D6:D21) -> 16428 | E22: =SUM(E6:E21) -> 1240368 | F22: =SUM(F6:F21) -> 1236069 | G22: =SUM(G6:G21) -> 67200 | H22: =SUM(H6:H21) -> 1303269 | I22: =SUM(I6:I21) -> 25050071 | J22: =SUM(J6:J21) -> 260620.8 | K22: =SUM(K6:K21) -> 25310692 | L22: =F22/E22 -> 0.99653409 | M22: =I22/F22 -> 20.265917 | N22: =M22/129.3029 -> 0.15673211 | O22: =SUM(O6:O21) -> 86952.369 | P22: =C22/O22*12 -> 173.44613 | Q22: =(K22*12/O22)/129.3029 -> 27.014416
B23: % | D23: =D22/C22 -> 0.013071334 | E23: =E22/C22 -> 0.98692867
B24: SPRAY ROSES
B25: Spray Rose Mirabel | C25: 75777 | D25: 882 | E25: =C25-D25 -> 74895 | F25: 75430 | G25: 6240 | H25: =F25+G25 -> 81670 | I25: 3634112.9 | J25: 64551.74 | K25: =I25+J25 -> 3698664.6 | L25: =F25/E25 -> 1.0071433 | M25: =I25/F25 -> 48.178615 | N25: =M25/129.3029 -> 0.37260274 | O25: 8436.1846 | P25: =C25/O25*12 -> 107.78854 | Q25: =(K25*12/O25)/129.3029 -> 40.688517
B26: Spray Rose Dominica | C26: 17052 | D26: 347 | E26: =C26-D26 -> 16705 | F26: 17380 | G26: 980 | H26: =F26+G26 -> 18360 | I26: 1017713.9 | J26: 11931.04 | K26: =I26+J26 -> 1029645 | L26: =F26/E26 -> 1.0404071 | M26: =I26/F26 -> 58.556612 | N26: =M26/129.3029 -> 0.45286387 | O26: 2357.1692 | P26: =C26/O26*12 -> 86.809211 | Q26: =(K26*12/O26)/129.3029 -> 40.53869
B27: Spray Rose Snowflake White | C27: 57071 | D27: 962 | E27: =C27-D27 -> 56109 | F27: 63130 | G27: 1200 | H27: =F27+G27 -> 64330 | I27: 2247751.5 | J27: 4137.92 | K27: =I27+J27 -> 2251889.4 | L27: =F27/E27 -> 1.1251314 | M27: =I27/F27 -> 35.605124 | N27: =M27/129.3029 -> 0.27536215 | O27: 5210.5846 | P27: =C27/O27*12 -> 131.43477 | Q27: =(K27*12/O27)/129.3029 -> 40.108238
B28: Spray Rose Odilia Pink | C28: 53881 | D28: 607 | E28: =C28-D28 -> 53274 | F28: 49610 | G28: 3480 | H28: =F28+G28 -> 53090 | I28: 1844403.2 | J28: 11999.98 | K28: =I28+J28 -> 1856403.2 | L28: =F28/E28 -> 0.93122349 | M28: =I28/F28 -> 37.178053 | N28: =M28/129.3029 -> 0.28752683 | O28: 5024.4923 | P28: =C28/O28*12 -> 128.68405 | Q28: =(K28*12/O28)/129.3029 -> 34.288864
B29: Spray Rose Good Mood | C29: 48866 | D29: 571 | E29: =C29-D29 -> 48295 | F29: 39140 | G29: 2540 | H29: =F29+G29 -> 41680 | I29: 1762019.7 | J29: 8758.62 | K29: =I29+J29 -> 1770778.3 | L29: =F29/E29 -> 0.81043586 | M29: =I29/F29 -> 45.018387 | N29: =M29/129.3029 -> 0.34816224 | O29: 5027.4462 | P29: =C29/O29*12 -> 116.63815 | Q29: =(K29*12/O29)/129.3029 -> 32.688105
B30: Spray Rose Lianne Pink | C30: 49471 | D30: 463 | E30: =C30-D30 -> 49008 | F30: 46940 | G30: 2420 | H30: =F30+G30 -> 49360 | I30: 1746017.4 | J30: 9379.31 | K30: =I30+J30 -> 1755396.7 | L30: =F30/E30 -> 0.95780281 | M30: =I30/F30 -> 37.196791 | N30: =M30/129.3029 -> 0.28767175 | O30: 5024.4923 | P30: =C30/O30*12 -> 118.15164 | Q30: =(K30*12/O30)/129.3029 -> 32.423215
B31: Spray Rose Fire Works Bi-Pink | C31: 19415 | D31: 269 | E31: =C31-D31 -> 19146 | F31: 20550 | G31: 20 | H31: =F31+G31 -> 20570 | I31: 860757.85 | J31: 68.97 | K31: =I31+J31 -> 860826.82 | L31: =F31/E31 -> 1.0733312 | M31: =I31/F31 -> 41.886027 | N31: =M31/129.3029 -> 0.32393726 | O31: 2481.2308 | P31: =C31/O31*12 -> 93.896949 | Q31: =(K31*12/O31)/129.3029 -> 32.19746
B32: Spray Rose Eileen | C32: 28827 | D32: 260 | E32: =C32-D32 -> 28567 | F32: 24140 | G32: 580 | H32: =F32+G32 -> 24720 | I32: 891889.1 | J32: 2103.44 | K32: =I32+J32 -> 893992.54 | L32: =F32/E32 -> 0.84503098 | M32: =I32/F32 -> 36.946524 | N32: =M32/129.3029 -> 0.28573624 | O32: 2605.2923 | P32: =C32/O32*12 -> 132.77742 | Q32: =(K32*12/O32)/129.3029 -> 31.845672
B33: Spray Rose Dinara | C33: 32152 | D33: 499 | E33: =C33-D33 -> 31653 | F33: 27730 | G33: 2080 | H33: =F33+G33 -> 29810 | I33: 1062111.8 | J33: 7172.4 | K33: =I33+J33 -> 1069284.2 | L33: =F33/E33 -> 0.8760623 | M33: =I33/F33 -> 38.301903 | N33: =M33/129.3029 -> 0.29621844 | O33: 3225.6 | P33: =C33/O33*12 -> 119.6131 | Q33: =(K33*12/O33)/129.3029 -> 30.764907
B34: Spray Rose Marisa Yellow | C34: 17681 | D34: 243 | E34: =C34-D34 -> 17438 | F34: 22810 | G34: 1300 | H34: =F34+G34 -> 24110 | I34: 789014.69 | J34: 4482.75 | K34: =I34+J34 -> 793497.44 | L34: =F34/E34 -> 1.3080629 | M34: =I34/F34 -> 34.590736 | N34: =M34/129.3029 -> 0.26751709 | O34: 2667.3231 | P34: =C34/O34*12 -> 79.54492 | Q34: =(K34*12/O34)/129.3029 -> 27.608505
B35: Spray Rose Reflex Bicolour | C35: 62267 | D35: 368 | E35: =C35-D35 -> 61899 | F35: 56610 | G35: 660 | H35: =F35+G35 -> 57270 | I35: 2154756.9 | J35: 2275.86 | K35: =I35+J35 -> 2157032.8 | L35: =F35/E35 -> 0.91455435 | M35: =I35/F35 -> 38.063185 | N35: =M35/129.3029 -> 0.29437225 | O35: 7381.6615 | P35: =C35/O35*12 -> 101.22436 | Q35: =(K35*12/O35)/129.3029 -> 27.11912
B36: Spray Rose Tessa | C36: 29812 | D36: 621 | E36: =C36-D36 -> 29191 | F36: 19890 | G36: 2460 | H36: =F36+G36 -> 22350 | I36: 749530.47 | J36: 8482.75 | K36: =I36+J36 -> 758013.22 | L36: =F36/E36 -> 0.6813744 | M36: =I36/F36 -> 37.683784 | N36: =M36/129.3029 -> 0.29143804 | O36: 2667.3231 | P36: =C36/O36*12 -> 134.12099 | Q36: =(K36*12/O36)/129.3029 -> 26.373887
... B50: Spray Rose Trinity Cream Yellow | C50: 19461 | D50: 69 | E50: =C50-D50 -> 19392 | F50: 3990 | G50: 7560 | H50: =F50+G50 -> 11550 | I50: 205439.94 | J50: 26068.98 | K50: =I50+J50 -> 231508.92 | L50: =F50/E50 -> 0.20575495 | M50: =I50/F50 -> 51.488707 | N50: =M50/129.3029 -> 0.39820226 | O50: 2481.2308 | P50: =C50/O50*12 -> 94.11942 | Q50: =(K50*12/O50)/129.3029 -> 8.6591159
B51: Spray Rose Wedding Party | C51: 24517 | D51: 436 | E51: =C51-D51 -> 24081 | F51: 11290 | G51: 17680 | H51: =F51+G51 -> 28970 | I51: 385557.93 | J51: 61689.68 | K51: =I51+J51 -> 447247.61 | L51: =F51/E51 -> 0.46883435 | M51: =I51/F51 -> 34.150392 | N51: =M51/129.3029 -> 0.26411157 | O51: 5009.7231 | P51: =C51/O51*12 -> 58.726599 | Q51: =(K51*12/O51)/129.3029 -> 8.2852819 | R51: To Replace
B52: Spray Rose Jalita | C52: 41052 | D52: 624 | E52: =C52-D52 -> 40428 | F52: 10650 | G52: 12660 | H52: =F52+G52 -> 23310 | I52: 384390.29 | J52: 47896.55 | K52: =I52+J52 -> 432286.84 | L52: =F52/E52 -> 0.26343129 | M52: =I52/F52 -> 36.092985 | N52: =M52/129.3029 -> 0.27913515 | O52: 4993.4769 | P52: =C52/O52*12 -> 98.653505 | Q52: =(K52*12/O52)/129.3029 -> 8.0341872
B53: Spray Rose Snow Bubble | C53: 15182 | D53: 189 | E53: =C53-D53 -> 14993 | F53: 4150 | G53: 14800 | H53: =F53+G53 -> 18950 | I53: 142670 | J53: 55758.64 | K53: =I53+J53 -> 198428.64 | L53: =F53/E53 -> 0.27679584 | M53: =I53/F53 -> 34.378313 | N53: =M53/129.3029 -> 0.26587426 | O53: 2481.2308 | P53: =C53/O53*12 -> 73.424851 | Q53: =(K53*12/O53)/129.3029 -> 7.4218159
B54: SUB TOTAL | C54: =SUM(C25:C53) -> 891377 | D54: =SUM(D25:D53) -> 11158 | E54: =SUM(E25:E53) -> 880219 | F54: =SUM(F25:F53) -> 713220 | G54: =SUM(G25:G53) -> 112950 | H54: =SUM(H25:H53) -> 826170 | I54: =SUM(I25:I53) -> 28151071 | J54: =SUM(J25:J53) -> 457556.6 | K54: =SUM(K25:K53) -> 28608628 | L54: =F54/E54 -> 0.81027562 | M54: =I54/F54 -> 39.47039 | N54: =M54/129.3029 -> 0.30525526 | O54: =SUM(O25:O53) -> 106988.31 | P54: =(C54/O54)*12 -> 99.978439 | Q54: =(K54*12/O54)/129.3029 -> 24.816109
...

Sheet Feb -Colour Code
B1: ZEEFLORA LIMITED
B2: PERFORMANCE PER VARIETY ANALYSIS
B3: 45716
B4: Description | C4: Production -Qty | D4: Rejection | E4: Sellable / Available for Sale | F4: Sales - Qty Export | G4: Sales - Qty Local | H4: Total Sales - Qty | I4: Export Sales -KES | J4: Local Sales KES | K4: Total Sales- KES | L4: % Export Sales | M4: Average Export Price KES | N4: Average Export Price USD | O4: Area SQM | P4: Production Per SQM | Q4: Revenue / SQM- USD
B5: STANDARD ROSES
B6: Rose Kamala Red | C6: ='Feb 2025 -Prodn& Sales Analysis'!C7 -> 137469 | D6: ='Feb 2025 -Prodn& Sales Analysis'!D7 -> 790 | E6: ='Feb 2025 -Prodn& Sales Analysis'!E7 -> 136679 | F6: ='Feb 2025 -Prodn& Sales Analysis'!F7 -> 146832 | G6: ='Feb 2025 -Prodn& Sales Analysis'!G7 -> 7280 | H6: ='Feb 2025 -Prodn& Sales Analysis'!H7 -> 154112 | I6: ='Feb 2025 -Prodn& Sales Analysis'!I7 -> 4537885 | J6: ='Feb 2025 -Prodn& Sales Analysis'!J7 -> 74706.91 | K6: ='Feb 2025 -Prodn& Sales Analysis'!K7 -> 4612591.9 | L6: =(F6+F7)/(C6+C7) -> 1.1672383 | M6: =I6/F6 -> 30.905286 | N6: =M6/129.3029 -> 0.23901464 | O6: ='Jan 2025-Prodn & Sales Analysis'!O11 -> 10048.985 | P6: =C6/O6*12 -> 164.15868 | Q6: =(K6+K7)*12/(O6+O7)/129.3029 -> 44.562475
B7: Rose Madam Red | C7: ='Feb 2025 -Prodn& Sales Analysis'!C6 -> 105693 | D7: ='Feb 2025 -Prodn& Sales Analysis'!D6 -> 651 | E7: ='Feb 2025 -Prodn& Sales Analysis'!E6 -> 105042 | F7: ='Feb 2025 -Prodn& Sales Analysis'!F6 -> 136996 | G7: ='Feb 2025 -Prodn& Sales Analysis'!G6 -> 480 | H7: ='Feb 2025 -Prodn& Sales Analysis'!H6 -> 137476 | I7: ='Feb 2025 -Prodn& Sales Analysis'!I6 -> 4232224.8 | J7: ='Feb 2025 -Prodn& Sales Analysis'!J6 -> 1448.28 | K7: ='Feb 2025 -Prodn& Sales Analysis'!K6 -> 4233673.1 | M7: =I7/F7 -> 30.893054 | N7: =M7/129.3029 -> 0.23892004 | O7: ='Jan 2025-Prodn & Sales Analysis'!O7 -> 8374.1538 | P7: =C7/O7*12 -> 151.45602
B8: Rose Madam Cerise | C8: ='Feb 2025 -Prodn& Sales Analysis'!C9 -> 38310 | D8: ='Feb 2025 -Prodn& Sales Analysis'!D9 -> 755 | E8: ='Feb 2025 -Prodn& Sales Analysis'!E9 -> 37555 | F8: ='Feb 2025 -Prodn& Sales Analysis'!F9 -> 33306 | G8: ='Feb 2025 -Prodn& Sales Analysis'!G9 -> 100 | H8: ='Feb 2025 -Prodn& Sales Analysis'!H9 -> 33406 | I8: ='Feb 2025 -Prodn& Sales Analysis'!I9 -> 729754.14 | J8: ='Feb 2025 -Prodn& Sales Analysis'!J9 -> 301.72 | K8: ='Feb 2025 -Prodn& Sales Analysis'!K9 -> 730055.86 | L8: =(F8+F9)/(E8+E9) -> 0.89009493 | M8: =I8/F8 -> 21.910591 | N8: =M8/129.3029 -> 0.16945166 | O8: ='Jan 2025-Prodn & Sales Analysis'!O6 -> 2109.0462 | P8: =C8/O8*12 -> 217.97532 | Q8: =(K8+K9)*12/(O8+O9)/129.3029 -> 32.540397
B9: Rose Ace Cerise | C9: ='Feb 2025 -Prodn& Sales Analysis'!C8 -> 70724 | D9: ='Feb 2025 -Prodn& Sales Analysis'!D8 -> 1041 | E9: ='Feb 2025 -Prodn& Sales Analysis'!E8 -> 69683 | F9: ='Feb 2025 -Prodn& Sales Analysis'!F8 -> 62146 | G9: ='Feb 2025 -Prodn& Sales Analysis'!G8 -> 5900 | H9: ='Feb 2025 -Prodn& Sales Analysis'!H8 -> 68046 | I9: ='Feb 2025 -Prodn& Sales Analysis'!I8 -> 1165098.1 | J9: ='Feb 2025 -Prodn& Sales Analysis'!J8 -> 18836.21 | K9: ='Feb 2025 -Prodn& Sales Analysis'!K8 -> 1183934.3 | M9: =I9/F9 -> 18.747757 | N9: =M9/129.3029 -> 0.144991 | O9: ='Jan 2025-Prodn & Sales Analysis'!O13 -> 3349.6615 | P9: =C9/O9*12 -> 253.3653
B10: Rose Pegasso White | C10: ='Feb 2025 -Prodn& Sales Analysis'!C10 -> 64760 | D10: ='Feb 2025 -Prodn& Sales Analysis'!D10 -> 2249 | E10: ='Feb 2025 -Prodn& Sales Analysis'!E10 -> 62511 | F10: ='Feb 2025 -Prodn& Sales Analysis'!F10 -> 60140 | G10: ='Feb 2025 -Prodn& Sales Analysis'!G10 -> 15240 | H10: ='Feb 2025 -Prodn& Sales Analysis'!H10 -> 75380 | I10: ='Feb 2025 -Prodn& Sales Analysis'!I10 -> 1544795.7 | J10: ='Feb 2025 -Prodn& Sales Analysis'!J10 -> 47819.01 | K10: ='Feb 2025 -Prodn& Sales Analysis'!K10 -> 1592614.7 | L10: =F10/E10 -> 0.96207068 | M10: =I10/F10 -> 25.686659 | N10: =M10/129.3029 -> 0.19865493 | O10: ='Jan 2025-Prodn & Sales Analysis'!O12 -> 4962.4615 | P10: =C10/O10*12 -> 156.5997 | Q10: =(K10*12/O10)/129.3029 -> 29.784241
B11: Rose Jumilia Bicolour Pink | C11: ='Feb 2025 -Prodn& Sales Analysis'!C11 -> 136880 | D11: ='Feb 2025 -Prodn& Sales Analysis'!D11 -> 1285 | E11: ='Feb 2025 -Prodn& Sales Analysis'!E11 -> 135595 | F11: ='Feb 2025 -Prodn& Sales Analysis'!F11 -> 142180 | G11: ='Feb 2025 -Prodn& Sales Analysis'!G11 -> 4640 | H11: ='Feb 2025 -Prodn& Sales Analysis'!H11 -> 146820 | I11: ='Feb 2025 -Prodn& Sales Analysis'!I11 -> 2634218.5 | J11: ='Feb 2025 -Prodn& Sales Analysis'!J11 -> 14206.89 | K11: ='Feb 2025 -Prodn& Sales Analysis'!K11 -> 2648425.4 | L11: =(F11+F12)/(E11+E12) -> 1.0232472 | M11: =I11/F11 -> 18.527349 | N11: =M11/129.3029 -> 0.14328642 | O11: ='Jan 2025-Prodn & Sales Analysis'!O8 -> 8684.3077 | P11: =C11/O11*12 -> 189.14116 | Q11: =(K11+K12)*12/(O11+O12)/129.3029 -> 27.773136
B12: Rose Trivia Pale Pink | C12: ='Feb 2025 -Prodn& Sales Analysis'!C12 -> 97855 | D12: ='Feb 2025 -Prodn& Sales Analysis'!D12 -> 691 | E12: ='Feb 2025 -Prodn& Sales Analysis'!E12 -> 97164 | F12: ='Feb 2025 -Prodn& Sales Analysis'!F12 -> 95990 | G12: ='Feb 2025 -Prodn& Sales Analysis'!G12 -> 1480 | H12: ='Feb 2025 -Prodn& Sales Analysis'!H12 -> 97470 | I12: ='Feb 2025 -Prodn& Sales Analysis'!I12 -> 1542245.9 | J12: ='Feb 2025 -Prodn& Sales Analysis'!J12 -> 4672.42 | K12: ='Feb 2025 -Prodn& Sales Analysis'!K12 -> 1546918.3 | M12: =I12/F12 -> 16.066735 | N12: =M12/129.3029 -> 0.12425657 | O12: ='Jan 2025-Prodn & Sales Analysis'!O9 -> 5334.6462 | P12: =C12/O12*12 -> 220.11957
B13: Rose Celeb Salmon Pink | C13: ='Feb 2025 -Prodn& Sales Analysis'!C14 -> 60710 | D13: ='Feb 2025 -Prodn& Sales Analysis'!D14 -> 1122 | E13: ='Feb 2025 -Prodn& Sales Analysis'!E14 -> 59588 | F13: ='Feb 2025 -Prodn& Sales Analysis'!F14 -> 58310 | G13: ='Feb 2025 -Prodn& Sales Analysis'!G14 -> 1560 | H13: ='Feb 2025 -Prodn& Sales Analysis'!H14 -> 59870 | I13: ='Feb 2025 -Prodn& Sales Analysis'!I14 -> 1219560.2 | J13: ='Feb 2025 -Prodn& Sales Analysis'!J14 -> 4706.89 | K13: ='Feb 2025 -Prodn& Sales Analysis'!K14 -> 1224267.1 | L13: =F13/E13 -> 0.97855273 | M13: =I13/F13 -> 20.915113 | N13: =M13/129.3029 -> 0.16175285 | O13: ='Jan 2025-Prodn & Sales Analysis'!O14 -> 4794.0923 | P13: =C13/O13*12 -> 151.96203 | Q13: =(K13*12/O13)/129.3029 -> 23.699696
B14: Rose Athena White | C14: ='Feb 2025 -Prodn& Sales Analysis'!C13 -> 173760 | D14: ='Feb 2025 -Prodn& Sales Analysis'!D13 -> 2121 | E14: ='Feb 2025 -Prodn& Sales Analysis'!E13 -> 171639 | F14: ='Feb 2025 -Prodn& Sales Analysis'!F13 -> 178886 | G14: ='Feb 2025 -Prodn& Sales Analysis'!G13 -> 11260 | H14: ='Feb 2025 -Prodn& Sales Analysis'!H13 -> 190146 | I14: ='Feb 2025 -Prodn& Sales Analysis'!I13 -> 2630888.1 | J14: ='Feb 2025 -Prodn& Sales Analysis'!J13 -> 35810.34 | K14: ='Feb 2025 -Prodn& Sales Analysis'!K13 -> 2666698.4 | L14: =F14/E14 -> 1.0422223 | M14: =I14/F14 -> 14.707065 | N14: =M14/129.3029 -> 0.11374119 | O14: ='Jan 2025-Prodn & Sales Analysis'!O10 -> 10545.231 | P14: =C14/O14*12 -> 197.73109 | Q14: =(K14*12/O14)/129.3029 -> 23.468796
B15: Rose Espana Bi-Color | C15: ='Feb 2025 -Prodn& Sales Analysis'!C15 -> 84656 | D15: ='Feb 2025 -Prodn& Sales Analysis'!D15 -> 872 | E15: ='Feb 2025 -Prodn& Sales Analysis'!E15 -> 83784 | F15: ='Feb 2025 -Prodn& Sales Analysis'!F15 -> 80564 | G15: ='Feb 2025 -Prodn& Sales Analysis'!G15 -> 3160 | H15: ='Feb 2025 -Prodn& Sales Analysis'!H15 -> 83724 | I15: ='Feb 2025 -Prodn& Sales Analysis'!I15 -> 1061007.9 | J15: ='Feb 2025 -Prodn& Sales Analysis'!J15 -> 9534.5 | K15: ='Feb 2025 -Prodn& Sales Analysis'!K15 -> 1070542.4 | L15: =(F15+F16+F17)/(C15+C16+C17) -> 0.91665008 | M15: =I15/F15 -> 13.169753 | N15: =M15/129.3029 -> 0.10185195 | O15: ='Jan 2025-Prodn & Sales Analysis'!O19 -> 5302.1538 | P15: =C15/O15*12 -> 191.5961 | Q15: =(K15+K16+K17)*12/(O15+O16+O17)/129.3029 -> 16.791697
